06-06 12:17:00  
                                           ⛔━━━━━━━━━━━━━━━━━━━━━━━━━━━━━━━━━━━━━━━━━━━━━━━━━━
                                           ⛔    iCloud3 v3.0.5.1, Thursday, 2024-06-06 12:17:00
                                           ⛔━━━━━━━━━━━━━━━━━━━━━━━━━━━━━━━━━━━━━━━━━━━━━━━━━━
06-06 12:17:00 [messaging...:0344] _INIT_   Profile:
                                           {'version': 1, 'ic3_version': '3.0.5.1', 'version_install_date': '2024-06-06 01:01:35', 'config_update_date': '2024-06-06 11:43:13', 'event_log_version': '3.0.17', 'event_log_version_running': '', 'event_log_card_directory': 'www/icloud3', 'event_log_card_program': 'icloud3-event-log-card.js', 'event_log_btnconfig_url': '', 'picture_www_dirs': []}
06-06 12:17:00 [messaging...:0344] _INIT_   Tracking:
                                           {'username': 'se...........@gm.......', 'password': 'iF..........', 'encode_password': True, 'icloud_server_endpoint_suffix': 'None', 'setup_icloud_session_early': True, 'data_source': 'famshr, mobapp', 'devices': '1'}
06-06 12:17:00 [messaging...:0344] _INIT_   General Configuration:
                                           {'log_level': 'debug-auto-reset', 'log_level_devices': ['all'], 'unit_of_measurement': 'mi', 'time_format': '12-hour', 'display_zone_format': 'fname', 'device_tracker_state_source': 'ic3_fname', 'max_interval': 240, 'offline_interval': 20, 'exit_zone_interval': 3, 'mobapp_alive_interval': 60, 'old_location_threshold': 3, 'old_location_adjustment': 0, 'gps_accuracy_threshold': 100, 'display_gps_lat_long': True, 'travel_time_factor': 0.5, 'tfz_tracking_max_distance': 8, 'passthru_zone_time': 0.5, 'track_from_base_zone_used': True, 'track_from_base_zone': 'home', 'track_from_home_zone': True, 'center_in_zone': False, 'discard_poor_gps_inzone': False, 'distance_between_devices': True, 'inzone_intervals': {'iphone': 120, 'ipad': 120, 'watch': 15, 'airpods': 15, 'no_mobapp': 15, 'other': 120}, 'waze_used': True, 'waze_region': 'us', 'waze_min_distance': 1, 'waze_max_distance': 1000, 'waze_realtime': False, 'waze_history_database_used': True, 'waze_history_max_distance': 20, 'waze_history_track_direction': 'north_south', 'stat_zone_fname': 'StatZon#', 'stat_zone_still_time': 8, 'stat_zone_inzone_interval': 30, 'stat_zone_base_latitude': 1, 'stat_zone_base_longitude': 0, 'display_text_as': ['#1', '#2', '#3', '#4', '#5', '#6', '#7', '#8', '#9', '#10'], 'away_time_zone_1_offset': 0, 'away_time_zone_1_devices': ['none'], 'away_time_zone_2_offset': 0, 'away_time_zone_2_devices': ['none']}
                                           {'country_code': 'US', 'region_code': 'GA', 'zip_code': '30308', 'region_name': 'Georgia', 'city': 'Atlanta', 'time_zone': 'America/New_York', 'latitude': 33.7697, 'longitude': -84.3754, 'use_metric': False}
06-06 12:17:00 [messaging...:0344] _INIT_   
06-06 12:17:00 [messaging...:0344] _INIT_   Sebastien, kid_pro_kuo_phone14:
                                           {'ic3_devicename': 'kid_pro_kuo_phone14', 'fname': 'Sebastien', 'picture': 'None', 'evlog_display_order': 0, 'unique_id': '', 'device_type': 'iphone', 'inzone_interval': 120.0, 'fixed_interval': 0.0, 'tracking_mode': 'track', 'famshr_devicename': 'kid-pro-Kuo-Watch', 'famshr_device_id': 'AZsy/acm1QXkPNmUEHXE7G63gp9g0lpyDVxtz6aRtK80y7HyV3Pzv98XJBJ/MutNF/jq7Elaggu23g==', 'raw_model': 'Watch5,4', 'model': 'Apple Watch', 'model_display_name': 'Apple Watch 5', 'fmf_email': 'None', 'fmf_device_id': '', 'mobile_app_device': 'kid_pro_kuo_phone_14', 'track_from_base_zone': 'home', 'track_from_zones': ['home'], 'log_zones': ['home', 'name-device-zone'], 'old_devicename': 'kid_pro_kuo_phone14'}
06-06 12:17:00 [messaging...:0344] _INIT_   
06-06 12:17:00 Traceback (most recent call last):
  File "/config/custom_components/icloud3/support/restore_state.py", line 121, in write_storage_icloud3_restore_state_file
  File "/usr/src/homeassistant/homeassistant/util/loop.py", line 131, in protected_loop_func
    return func(*args, **kwargs)
           ^^^^^^^^^^^^^^^^^^^^^
FileNotFoundError: [Errno 2] No such file or directory: '/config/.storage/icloud3/restore_state'

06-06 12:18:00 Traceback (most recent call last):
  File "/config/custom_components/icloud3/support/restore_state.py", line 121, in write_storage_icloud3_restore_state_file
  File "/usr/src/homeassistant/homeassistant/util/loop.py", line 131, in protected_loop_func
    return func(*args, **kwargs)
           ^^^^^^^^^^^^^^^^^^^^^
FileNotFoundError: [Errno 2] No such file or directory: '/config/.storage/icloud3/restore_state'

06-06 12:19:00 Traceback (most recent call last):
  File "/config/custom_components/icloud3/support/restore_state.py", line 121, in write_storage_icloud3_restore_state_file
  File "/usr/src/homeassistant/homeassistant/util/loop.py", line 131, in protected_loop_func
    return func(*args, **kwargs)
           ^^^^^^^^^^^^^^^^^^^^^
FileNotFoundError: [Errno 2] No such file or directory: '/config/.storage/icloud3/restore_state'

06-06 12:20:00 Traceback (most recent call last):
  File "/config/custom_components/icloud3/support/restore_state.py", line 121, in write_storage_icloud3_restore_state_file
  File "/usr/src/homeassistant/homeassistant/util/loop.py", line 131, in protected_loop_func
    return func(*args, **kwargs)
           ^^^^^^^^^^^^^^^^^^^^^
FileNotFoundError: [Errno 2] No such file or directory: '/config/.storage/icloud3/restore_state'

06-06 12:21:00 Traceback (most recent call last):
  File "/config/custom_components/icloud3/support/restore_state.py", line 121, in write_storage_icloud3_restore_state_file
  File "/usr/src/homeassistant/homeassistant/util/loop.py", line 131, in protected_loop_func
    return func(*args, **kwargs)
           ^^^^^^^^^^^^^^^^^^^^^
FileNotFoundError: [Errno 2] No such file or directory: '/config/.storage/icloud3/restore_state'

06-06 12:22:00 Traceback (most recent call last):
  File "/config/custom_components/icloud3/support/restore_state.py", line 121, in write_storage_icloud3_restore_state_file
  File "/usr/src/homeassistant/homeassistant/util/loop.py", line 131, in protected_loop_func
    return func(*args, **kwargs)
           ^^^^^^^^^^^^^^^^^^^^^
FileNotFoundError: [Errno 2] No such file or directory: '/config/.storage/icloud3/restore_state'

06-06 12:23:00 Traceback (most recent call last):
  File "/config/custom_components/icloud3/support/restore_state.py", line 121, in write_storage_icloud3_restore_state_file
  File "/usr/src/homeassistant/homeassistant/util/loop.py", line 131, in protected_loop_func
    return func(*args, **kwargs)
           ^^^^^^^^^^^^^^^^^^^^^
FileNotFoundError: [Errno 2] No such file or directory: '/config/.storage/icloud3/restore_state'

06-06 12:24:00 Traceback (most recent call last):
  File "/config/custom_components/icloud3/support/restore_state.py", line 121, in write_storage_icloud3_restore_state_file
  File "/usr/src/homeassistant/homeassistant/util/loop.py", line 131, in protected_loop_func
    return func(*args, **kwargs)
           ^^^^^^^^^^^^^^^^^^^^^
FileNotFoundError: [Errno 2] No such file or directory: '/config/.storage/icloud3/restore_state'

06-06 12:25:00 Traceback (most recent call last):
  File "/config/custom_components/icloud3/support/restore_state.py", line 121, in write_storage_icloud3_restore_state_file
  File "/usr/src/homeassistant/homeassistant/util/loop.py", line 131, in protected_loop_func
    return func(*args, **kwargs)
           ^^^^^^^^^^^^^^^^^^^^^
FileNotFoundError: [Errno 2] No such file or directory: '/config/.storage/icloud3/restore_state'

06-06 12:26:00 Traceback (most recent call last):
  File "/config/custom_components/icloud3/support/restore_state.py", line 121, in write_storage_icloud3_restore_state_file
  File "/usr/src/homeassistant/homeassistant/util/loop.py", line 131, in protected_loop_func
    return func(*args, **kwargs)
           ^^^^^^^^^^^^^^^^^^^^^
FileNotFoundError: [Errno 2] No such file or directory: '/config/.storage/icloud3/restore_state'

06-06 12:27:00 Traceback (most recent call last):
  File "/config/custom_components/icloud3/support/restore_state.py", line 121, in write_storage_icloud3_restore_state_file
  File "/usr/src/homeassistant/homeassistant/util/loop.py", line 131, in protected_loop_func
    return func(*args, **kwargs)
           ^^^^^^^^^^^^^^^^^^^^^
FileNotFoundError: [Errno 2] No such file or directory: '/config/.storage/icloud3/restore_state'

06-06 12:28:00 Traceback (most recent call last):
  File "/config/custom_components/icloud3/support/restore_state.py", line 121, in write_storage_icloud3_restore_state_file
  File "/usr/src/homeassistant/homeassistant/util/loop.py", line 131, in protected_loop_func
    return func(*args, **kwargs)
           ^^^^^^^^^^^^^^^^^^^^^
FileNotFoundError: [Errno 2] No such file or directory: '/config/.storage/icloud3/restore_state'

06-06 12:28:12 [start_ic3...:0492] ------   HA Shutting Down
